Workbook

Sheet perhitungan
A1: 1. PISAHKAN KEDUA KELOMPOK "BAD" DAN "GOOD"
A2: BAD | F2: GOOD
K3: 3. MATRIKS RAGAM-PERAGAM GABUNGAN & INVERSNYA
A4: tanggungan | B4: pendapatan | C4: Usia | D4: Status | F4: tanggungan | G4: pendapatan | H4: Usia | I4: Status
A5: 6 | B5: 10 | C5: 40 | D5: Bad | F5: 1 | G5: 16.7 | H5: 61 | I5: Good | P5: (n1-1)S1
A6: 1 | B6: 9 | C6: 50 | D6: Bad | F6: 5 | G6: 11.8 | H6: 34 | I6: Good | Q6: {=(B62:D64)*L11} -> 79.234043 | R6: 48.621277 | S6: -4.8723404
A7: 2 | B7: 4.8 | C7: 36 | D7: Bad | F7: 2 | G7: 10.6 | H7: 31 | I7: Good | P7: S1(bad) | Q7: 48.621277 | R7: 463.3783 | S7: -76.470213
A8: 0 | B8: 4.9 | C8: 53 | D8: Bad | F8: 3 | G8: 6 | H8: 60 | I8: Good | Q8: -4.8723404 | R8: -4.8723404 | S8: 2324.9787
A9: 1 | B9: 4.7 | C9: 35 | D9: Bad | F9: 2 | G9: 13.6 | H9: 47 | I9: Good
A10: 3 | B10: 2.4 | C10: 45 | D10: Bad | F10: 0 | G10: 8.5 | H10: 50 | I10: Good | K10: n1(bad) | L10: 47 | M10: n2(good) | N10: 53 | P10: (n2-1)S2 | U10: Matriks Varian-Kovarian Gabungan Invers
A11: 3 | B11: 4.6 | C11: 38 | D11: Bad | F11: 2 | G11: 10.1 | H11: 51 | I11: Good | K11: n1-1 | L11: =L10-1 -> 46 | M11: n2-1 | N11: =N10-1 -> 52 | Q11: {=(G68:I70)*N11} -> 81.54717 | R11: -8.4924528 | S11: 21.773585 | V11: {=MINVERSE(Q16:S18)} -> 0.6143754 | W11: -0.018845141 | X11: -0.0014075186
A12: 2 | B12: 4.9 | C12: 57 | D12: Bad | F12: 0 | G12: 14.1 | H12: 51 | I12: Good | K12: n1+n2-2 | L12: =L10+N10-2 -> 98 | P12: S2(good) | Q12: -8.4924528 | R12: 836.83321 | S12: 112.50377 | U12: S_gab_inv | V12: -0.018928107 | W12: 0.075985569 | X12: -0.00035071345
A13: 4 | B13: 8 | C13: 36 | D13: Bad | F13: 0 | G13: 8.4 | H13: 48 | I13: Good | Q13: 21.773585 | R13: 112.50377 | S13: 4569.8868 | V13: -0.0012105312 | W13: -0.0011399685 | X13: 0.0142224
A14: 1 | B14: 8.3 | C14: 50 | D14: Bad | F14: 2 | G14: 9.2 | H14: 61 | I14: Good
A15: 3 | B15: 8 | C15: 50 | D15: Bad | F15: 2 | G15: 7.7 | H15: 59 | I15: Good | P15: Matriks Varian-Kovarian Gabungan
A16: 1 | B16: 4.2 | C16: 37 | D16: Bad | F16: 2 | G16: 10.7 | H16: 40 | I16: Good | K16: 4. KOEFISIEN MODEL VEKTOR & TANSPOSENYA | Q16: {=((Q6:S8)+(Q11:S13))/L12} -> 1.6406246 | R16: 0.40947779 | S16: 0.17246168
A17: 2 | B17: 3.1 | C17: 56 | D17: Bad | F17: 2 | G17: 12.5 | H17: 47 | I17: Good | P17: S_gab | Q17: 0.40947779 | R17: 13.267464 | S17: 0.3676894
A18: 2 | B18: 6.8 | C18: 41 | D18: Bad | F18: 2 | G18: 9.1 | H18: 57 | I18: Good | Q18: 0.17246168 | R18: 1.0982799 | S18: 70.355771
A19: 2 | B19: 7.4 | C19: 35 | D19: Bad | F19: 2 | G19: 11.8 | H19: 47 | I19: Good
A20: 1 | B20: 7 | C20: 35 | D20: Bad | F20: 1 | G20: 11.9 | H20: 43 | I20: Good
A21: 1 | B21: 7.8 | C21: 49 | D21: Bad | F21: 1 | G21: 9.4 | H21: 60 | I21: Good
A22: 1 | B22: 8.2 | C22: 50 | D22: Bad | F22: 1 | G22: 10.7 | H22: 41 | I22: Good | K22: Tanggungan | L22: =A54 -> 2.1276596 | M22: =F60 -> 1.6792453 | N22: =L22-M22 -> 0.44841429
A23: 0 | B23: 4.5 | C23: 44 | D23: Bad | F23: 4 | G23: 15.1 | H23: 58 | I23: Good | K23: Pendapatan | L23: =B54 -> 7.1297872 | M23: =G60 -> 11.388679 | N23: =L23-M23 -> -4.258892
A24: 3 | B24: 8.1 | C24: 40 | D24: Bad | F24: 3 | G24: 15.9 | H24: 61 | I24: Good | K24: Usia | L24: =C54 -> 45.978723 | M24: =H60 -> 48.339623 | N24: =L24-M24 -> -2.3608992
A25: 2 | B25: 6.6 | C25: 49 | D25: Bad | F25: 2 | G25: 13.7 | H25: 58 | I25: Good
A26: 4 | B26: 19.8 | C26: 42 | D26: Bad | F26: 3 | G26: 12.6 | H26: 52 | I26: Good | L26: {=MMULT(V11:X13,N22:N24)} -> 0.35907714 | N26: a1 | O26: =L26 -> 0.35907714
A27: 1 | B27: 7.8 | C27: 35 | D27: Bad | F27: 1 | G27: 12.1 | H27: 44 | I27: Good | K27: a | L27: -0.33127397 | N27: a2 | O27: =L27 -> -0.33127397
A28: 2 | B28: 4.6 | C28: 47 | D28: Bad | F28: 2 | G28: 11.3 | H28: 41 | I28: Good | L28: -0.029265471 | N28: a3 | O28: =L28 -> -0.029265471
A29: 0 | B29: 7.4 | C29: 46 | D29: Bad | F29: 0 | G29: 12.5 | H29: 54 | I29: Good
A30: 4 | B30: 5.5 | C30: 47 | D30: Bad | F30: 2 | G30: 11.3 | H30: 41 | I30: Good | K30: a' | L30: {=TRANSPOSE(_xlfn.ANCHORARRAY(L26))} -> 0.35907714 | M30: -0.33127397 | N30: -0.029265471
A31: 3 | B31: 16.4 | C31: 54 | D31: Bad | F31: 1 | G31: 10.5 | H31: 31 | I31: Good
A32: 1 | B32: 7.6 | C32: 35 | D32: Bad | F32: 2 | G32: 9.8 | H32: 31 | I32: Good | K32: 5. NILAI BATAS KLASIFIKASI
A33: 2 | B33: 4.9 | C33: 56 | D33: Bad | F33: 0 | G33: 10.1 | H33: 40 | I33: Good
A34: 2 | B34: 4.2 | C34: 56 | D34: Bad | F34: 4 | G34: 4.8 | H34: 61 | I34: Good
A35: 1 | B35: 9 | C35: 38 | D35: Bad | F35: 1 | G35: 12.9 | H35: 48 | I35: Good
A36: 4 | B36: 9.2 | C36: 40 | D36: Bad | F36: 2 | G36: 13.1 | H36: 58 | I36: Good
A37: 5 | B37: 4.6 | C37: 50 | D37: Bad | F37: 1 | G37: 7.9 | H37: 55 | I37: Good
A38: 2 | B38: 6.4 | C38: 59 | D38: Bad | F38: 1 | G38: 6.5 | H38: 52 | I38: Good
A39: 2 | B39: 6 | C39: 42 | D39: Bad | F39: 4 | G39: 13.2 | H39: 34 | I39: Good | K39: {=TRANSPOSE(A54:C54)} -> 2.1276596 | L39: {=TRANSPOSE(F60:H60)} -> 1.6792453 | N39: a1 | O39: a2 | P39: a3
A40: 1 | B40: 10.5 | C40: 46 | D40: Bad | F40: 2 | G40: 6.5 | H40: 39 | I40: Good | K40: 7.1297872 | L40: 11.388679 | M40: a' | N40: {=L30:N30} -> 0.35907714 | O40: -0.33127397 | P40: -0.029265471
...

Sheet hasil dan evaluasi 
A1: tanggungan | B1: pendapatan | C1: Usia | D1: Status | E1: y (skor) | F1: Fisher
A2: 6 | B2: 10 | C2: 40 | D2: Bad | E2: =($J$5*A2)-($K$5*B2)-($L$5*C2) -> 5.0173244 | F2: =IF(E2>=perhitungan!$L$48,"Bad","Good") -> Bad | I2: MODEL AKHIR
A3: 1 | B3: 9 | C3: 50 | D3: Bad | E3: =($J$5*A3)-($K$5*B3)-($L$5*C3) -> 4.4547468 | F3: =IF(E3>=perhitungan!$L$48,"Bad","Good") -> Bad | I3: y = a1x + a2x2 + a3x3
A4: 2 | B4: 4.8 | C4: 36 | D4: Bad | E4: =($J$5*A4)-($K$5*B4)-($L$5*C4) -> 2.7988644 | F4: =IF(E4>=perhitungan!$L$48,"Bad","Good") -> Bad | I4: y = 0.105x1 - 0.323x2 - 0.028x3
A5: 0 | B5: 4.9 | C5: 53 | D5: Bad | E5: =($J$5*A5)-($K$5*B5)-($L$5*C5) -> 3.1095141 | F5: =IF(E5>=perhitungan!$L$48,"Bad","Good") -> Bad | I5: a' | J5: 0.10535519 | K5: -0.32345712 | L5: -0.028765551
A6: 1 | B6: 4.7 | C6: 35 | D6: Bad | E6: =($J$5*A6)-($K$5*B6)-($L$5*C6) -> 2.632398 | F6: =IF(E6>=perhitungan!$L$48,"Bad","Good") -> Bad
A7: 3 | B7: 2.4 | C7: 45 | D7: Bad | E7: =($J$5*A7)-($K$5*B7)-($L$5*C7) -> 2.3868125 | F7: =IF(E7>=perhitungan!$L$48,"Bad","Good") -> Bad
A8: 3 | B8: 4.6 | C8: 38 | D8: Bad | E8: =($J$5*A8)-($K$5*B8)-($L$5*C8) -> 2.8970593 | F8: =IF(E8>=perhitungan!$L$48,"Bad","Good") -> Bad | I8: MANUAL | K8: prediksi
A9: 2 | B9: 4.9 | C9: 57 | D9: Bad | E9: =($J$5*A9)-($K$5*B9)-($L$5*C9) -> 3.4352867 | F9: =IF(E9>=perhitungan!$L$48,"Bad","Good") -> Bad | K9: Bad | L9: Good
A10: 4 | B10: 8 | C10: 36 | D10: Bad | E10: =($J$5*A10)-($K$5*B10)-($L$5*C10) -> 4.0446376 | F10: =IF(E10>=perhitungan!$L$48,"Bad","Good") -> Bad | I10: aktual | J10: Bad | K10: =COUNTIFS(D:D, "Bad", F:F, "Bad") -> 47 | L10: =COUNTIFS(D:D, "Bad", F:F, "Good") -> 0
A11: 1 | B11: 8.3 | C11: 50 | D11: Bad | E11: =($J$5*A11)-($K$5*B11)-($L$5*C11) -> 4.2283269 | F11: =IF(E11>=perhitungan!$L$48,"Bad","Good") -> Bad | J11: Good | K11: =COUNTIFS(D:D, "Good", F:F, "Bad") -> 53 | L11: =COUNTIFS(D:D, "Good", F:F, "Good") -> 0
A12: 3 | B12: 8 | C12: 50 | D12: Bad | E12: =($J$5*A12)-($K$5*B12)-($L$5*C12) -> 4.3420001 | F12: =IF(E12>=perhitungan!$L$48,"Bad","Good") -> Bad
A13: 1 | B13: 4.2 | C13: 37 | D13: Bad | E13: =($J$5*A13)-($K$5*B13)-($L$5*C13) -> 2.5282005 | F13: =IF(E13>=perhitungan!$L$48,"Bad","Good") -> Bad | I13: PIVOT TABLE
A14: 2 | B14: 3.1 | C14: 56 | D14: Bad | E14: =($J$5*A14)-($K$5*B14)-($L$5*C14) -> 2.8242983 | F14: =IF(E14>=perhitungan!$L$48,"Bad","Good") -> Bad | I14: Count of Status | J14: Column Labels
A15: 2 | B15: 6.8 | C15: 41 | D15: Bad | E15: =($J$5*A15)-($K$5*B15)-($L$5*C15) -> 3.5896064 | F15: =IF(E15>=perhitungan!$L$48,"Bad","Good") -> Bad | I15: Row Labels | J15: Bad | K15: Good | L15: Grand Total
A16: 2 | B16: 7.4 | C16: 35 | D16: Bad | E16: =($J$5*A16)-($K$5*B16)-($L$5*C16) -> 3.6110874 | F16: =IF(E16>=perhitungan!$L$48,"Bad","Good") -> Bad | I16: Bad | J16: 40 | K16: 7 | L16: 47
A17: 1 | B17: 7 | C17: 35 | D17: Bad | E17: =($J$5*A17)-($K$5*B17)-($L$5*C17) -> 3.3763493 | F17: =IF(E17>=perhitungan!$L$48,"Bad","Good") -> Bad | I17: Good | J17: 13 | K17: 40 | L17: 53
A18: 1 | B18: 7.8 | C18: 49 | D18: Bad | E18: =($J$5*A18)-($K$5*B18)-($L$5*C18) -> 4.0378327 | F18: =IF(E18>=perhitungan!$L$48,"Bad","Good") -> Bad | I18: Grand Total | J18: 53 | K18: 47 | L18: 100
A19: 1 | B19: 8.2 | C19: 50 | D19: Bad | E19: =($J$5*A19)-($K$5*B19)-($L$5*C19) -> 4.1959811 | F19: =IF(E19>=perhitungan!$L$48,"Bad","Good") -> Bad
A20: 0 | B20: 4.5 | C20: 44 | D20: Bad | E20: =($J$5*A20)-($K$5*B20)-($L$5*C20) -> 2.7212413 | F20: =IF(E20>=perhitungan!$L$48,"Bad","Good") -> Bad
A21: 3 | B21: 8.1 | C21: 40 | D21: Bad | E21: =($J$5*A21)-($K$5*B21)-($L$5*C21) -> 4.0866903 | F21: =IF(E21>=perhitungan!$L$48,"Bad","Good") -> Bad
A22: 2 | B22: 6.6 | C22: 49 | D22: Bad | E22: =($J$5*A22)-($K$5*B22)-($L$5*C22) -> 3.7550394 | F22: =IF(E22>=perhitungan!$L$48,"Bad","Good") -> Bad
A23: 4 | B23: 19.8 | C23: 42 | D23: Bad | E23: =($J$5*A23)-($K$5*B23)-($L$5*C23) -> 8.0340249 | F23: =IF(E23>=perhitungan!$L$48,"Bad","Good") -> Bad
A24: 1 | B24: 7.8 | C24: 35 | D24: Bad | E24: =($J$5*A24)-($K$5*B24)-($L$5*C24) -> 3.635115 | F24: =IF(E24>=perhitungan!$L$48,"Bad","Good") -> Bad
A25: 2 | B25: 4.6 | C25: 47 | D25: Bad | E25: =($J$5*A25)-($K$5*B25)-($L$5*C25) -> 3.050594 | F25: =IF(E25>=perhitungan!$L$48,"Bad","Good") -> Bad
A26: 0 | B26: 7.4 | C26: 46 | D26: Bad | E26: =($J$5*A26)-($K$5*B26)-($L$5*C26) -> 3.716798 | F26: =IF(E26>=perhitungan!$L$48,"Bad","Good") -> Bad
A27: 4 | B27: 5.5 | C27: 47 | D27: Bad | E27: =($J$5*A27)-($K$5*B27)-($L$5*C27) -> 3.5524158 | F27: =IF(E27>=perhitungan!$L$48,"Bad","Good") -> Bad
A28: 3 | B28: 16.4 | C28: 54 | D28: Bad | E28: =($J$5*A28)-($K$5*B28)-($L$5*C28) -> 7.1741021 | F28: =IF(E28>=perhitungan!$L$48,"Bad","Good") -> Bad
A29: 1 | B29: 7.6 | C29: 35 | D29: Bad | E29: =($J$5*A29)-($K$5*B29)-($L$5*C29) -> 3.5704236 | F29: =IF(E29>=perhitungan!$L$48,"Bad","Good") -> Bad
A30: 2 | B30: 4.9 | C30: 56 | D30: Bad | E30: =($J$5*A30)-($K$5*B30)-($L$5*C30) -> 3.4065211 | F30: =IF(E30>=perhitungan!$L$48,"Bad","Good") -> Bad
... A101: 1 | B101: 23 | C101: 44 | D101: Good | E101: =($J$5*A101)-($K$5*B101)-($L$5*C101) -> 8.8105532 | F101: =IF(E101>=perhitungan!$L$48,"Bad","Good") -> Bad
